{"text": "2025-09-16 11:37:15.862 | ERROR    | checker:execute_single_check:310 - Check 'wrong_type_check' Is Not A Bool\n", "record": {"elapsed": {"repr": "0:00:00.186835", "seconds": 0.186835}, "exception": null, "extra": {"service": "health-checker", "version": "0.0.1", "environment": "development", "component": "health_checker", "operation": "check_bool", "check_name": "wrong_type_check", "incorrect_type": "str", "critical": false, "error_type": "not_bool", "correlation_id": "7ca5f456", "execution_id": "exec_1758044235_cdfd2aac"}, "file": {"name": "checker.py", "path": "/home/toby/Projects/CleanBoard/backend/src/health/checker.py"}, "function": "execute_single_check", "level": {"icon": "❌", "name": "ERROR", "no": 40}, "line": 310, "message": "Check 'wrong_type_check' Is Not A Bool", "module": "checker", "name": "checker", "process": {"id": 16891, "name": "MainProcess"}, "thread": {"id": 140530942503872, "name": "MainThread"}, "time": {"repr": "2025-09-16 11:37:15.862636-06:00", "timestamp": 1758044235.862636}}}
{"text": "2025-09-16 11:37:15.863 | ERROR    | logging_config:__exit__:322 - Failed individual_check_execution for wrong_type_check after 105.81ms: Check function must return a boolean, got str\n", "record": {"elapsed": {"repr": "0:00:00.187763", "seconds": 0.187763}, "exception": null, "extra": {"service": "health-checker", "version": "0.0.1", "environment": "development", "component": "health_checker", "operation": "individual_check_execution", "check_name": "wrong_type_check", "duration": 105.807, "error_type": "ValueError", "correlation_id": "7ca5f456", "execution_id": "exec_1758044235_cdfd2aac", "critical": false, "timeout": 2.0}, "file": {"name": "logging_config.py", "path": "/home/toby/Projects/CleanBoard/backend/src/logging_config.py"}, "function": "__exit__", "level": {"icon": "❌", "name": "ERROR", "no": 40}, "line": 322, "message": "Failed individual_check_execution for wrong_type_check after 105.81ms: Check function must return a boolean, got str", "module": "logging_config", "name": "logging_config", "process": {"id": 16891, "name": "MainProcess"}, "thread": {"id": 140530942503872, "name": "MainThread"}, "time": {"repr": "2025-09-16 11:37:15.863564-06:00", "timestamp": 1758044235.863564}}}
{"text": "2025-09-16 11:37:15.864 | ERROR    | __main__:demonstrate_all_logging_scenarios:165 - An error has been caught in function 'demonstrate_all_logging_scenarios', process 'MainProcess' (16891), thread 'MainThread' (140530942503872):\nTraceback (most recent call last):\n\n  File \"/home/toby/Projects/CleanBoard/backend/src/health/test_logging_examples.py\", line 272, in <module>\n    asyncio.run(main())\n    │       │   └ <function main at 0x7fcfe838f6a0>\n    │       └ <function run at 0x7fcfe7511f80>\n    └ <module 'asyncio' from '/usr/lib/python3.13/asyncio/__init__.py'>\n\n  File \"/usr/lib/python3.13/asyncio/runners.py\", line 195, in run\n    return runner.run(main)\n           │      │   └ <coroutine object main at 0x7fcfe7429f20>\n           │      └ <function Runner.run at 0x7fcfe75d44a0>\n           └ <asyncio.runners.Runner object at 0x7fcfe6ad8590>\n  File \"/usr/lib/python3.13/asyncio/runners.py\", line 118, in run\n    return self._loop.run_until_complete(task)\n           │    │     │                  └ <Task pending name='Task-1' coro=<main() running at /home/toby/Projects/CleanBoard/backend/src/health/test_logging_examples.p...\n           │    │     └ <function BaseEventLoop.run_until_complete at 0x7fcfe75d2020>\n           │    └ <_UnixSelectorEventLoop running=True closed=False debug=False>\n           └ <asyncio.runners.Runner object at 0x7fcfe6ad8590>\n  File \"/usr/lib/python3.13/asyncio/base_events.py\", line 712, in run_until_complete\n    self.run_forever()\n    │    └ <function BaseEventLoop.run_forever at 0x7fcfe75d1f80>\n    └ <_UnixSelectorEventLoop running=True closed=False debug=False>\n  File \"/usr/lib/python3.13/asyncio/base_events.py\", line 683, in run_forever\n    self._run_once()\n    │    └ <function BaseEventLoop._run_once at 0x7fcfe75d3d80>\n    └ <_UnixSelectorEventLoop running=True closed=False debug=False>\n  File \"/usr/lib/python3.13/asyncio/base_events.py\", line 2050, in _run_once\n    handle._run()\n    │      └ <function Handle._run at 0x7fcfe7d02e80>\n    └ <Handle Task.task_wakeup()>\n  File \"/usr/lib/python3.13/asyncio/events.py\", line 89, in _run\n    self._context.run(self._callback, *self._args)\n    │    │            │    │           │    └ <member '_args' of 'Handle' objects>\n    │    │            │    │           └ <Handle Task.task_wakeup()>\n    │    │            │    └ <member '_callback' of 'Handle' objects>\n    │    │            └ <Handle Task.task_wakeup()>\n    │    └ <member '_context' of 'Handle' objects>\n    └ <Handle Task.task_wakeup()>\n\n  File \"/home/toby/Projects/CleanBoard/backend/src/health/test_logging_examples.py\", line 268, in main\n    await demo.demonstrate_all_logging_scenarios()\n          │    └ <function LoggingExamplesDemo.demonstrate_all_logging_scenarios at 0x7fcfe6af5580>\n          └ <__main__.LoggingExamplesDemo object at 0x7fcfe6ad8c20>\n\n> File \"/home/toby/Projects/CleanBoard/backend/src/health/test_logging_examples.py\", line 165, in demonstrate_all_logging_scenarios\n    result = await self.checker.run_checks()\n                   │    │       └ <function HealthChecker.run_checks at 0x7fcfe6af51c0>\n                   │    └ <checker.HealthChecker object at 0x7fcfe6ad8d70>\n                   └ <__main__.LoggingExamplesDemo object at 0x7fcfe6ad8c20>\n\n  File \"/home/toby/Projects/CleanBoard/backend/src/health/checker.py\", line 540, in run_checks\n    return await self._execute_checks(self.checks)\n                 │    │               │    └ [HealthCheck(name='fast_database_check', check_func=<function LoggingExamplesDemo.setup_example_checks.<locals>.fast_healthy_...\n                 │    │               └ <checker.HealthChecker object at 0x7fcfe6ad8d70>\n                 │    └ <function HealthChecker._execute_checks at 0x7fcfe6af4e00>\n                 └ <checker.HealthChecker object at 0x7fcfe6ad8d70>\n\n  File \"/home/toby/Projects/CleanBoard/backend/src/health/checker.py\", line 492, in _execute_checks\n    check_results = await asyncio.gather(\n                          │       └ <function gather at 0x7fcfe75ca700>\n                          └ <module 'asyncio' from '/usr/lib/python3.13/asyncio/__init__.py'>\n\n  File \"/home/toby/Projects/CleanBoard/backend/src/health/checker.py\", line 311, in execute_single_check\n    raise ValueError(\n\nValueError: Check function must return a boolean, got str\n", "record": {"elapsed": {"repr": "0:00:00.188708", "seconds": 0.188708}, "exception": {"type": "ValueError", "value": "Check function must return a boolean, got str", "traceback": true}, "extra": {"service": "health-checker", "version": "0.0.1", "environment": "development", "component": "unknown", "operation": "unknown"}, "file": {"name": "test_logging_examples.py", "path": "/home/toby/Projects/CleanBoard/backend/src/health/test_logging_examples.py"}, "function": "demonstrate_all_logging_scenarios", "level": {"icon": "❌", "name": "ERROR", "no": 40}, "line": 165, "message": "An error has been caught in function 'demonstrate_all_logging_scenarios', process 'MainProcess' (16891), thread 'MainThread' (140530942503872):", "module": "test_logging_examples", "name": "__main__", "process": {"id": 16891, "name": "MainProcess"}, "thread": {"id": 140530942503872, "name": "MainThread"}, "time": {"repr": "2025-09-16 11:37:15.864509-06:00", "timestamp": 1758044235.864509}}}
{"text": "2025-09-16 11:37:15.877 | ERROR    | logging_config:__exit__:322 - Failed individual_check_execution for timeout_check after 120.47ms: \n", "record": {"elapsed": {"repr": "0:00:00.202045", "seconds": 0.202045}, "exception": null, "extra": {"service": "health-checker", "version": "0.0.1", "environment": "development", "component": "health_checker", "operation": "individual_check_execution", "check_name": "timeout_check", "duration": 120.467, "error_type": "CancelledError", "correlation_id": "7ca5f456", "execution_id": "exec_1758044235_cdfd2aac", "critical": false, "timeout": 1.0}, "file": {"name": "logging_config.py", "path": "/home/toby/Projects/CleanBoard/backend/src/logging_config.py"}, "function": "__exit__", "level": {"icon": "❌", "name": "ERROR", "no": 40}, "line": 322, "message": "Failed individual_check_execution for timeout_check after 120.47ms: ", "module": "logging_config", "name": "logging_config", "process": {"id": 16891, "name": "MainProcess"}, "thread": {"id": 140530942503872, "name": "MainThread"}, "time": {"repr": "2025-09-16 11:37:15.877846-06:00", "timestamp": 1758044235.877846}}}
{"text": "2025-09-16 11:37:15.878 | ERROR    | logging_config:__exit__:322 - Failed individual_check_execution for cached_redis_check after 120.45ms: \n", "record": {"elapsed": {"repr": "0:00:00.202617", "seconds": 0.202617}, "exception": null, "extra": {"service": "health-checker", "version": "0.0.1", "environment": "development", "component": "health_checker", "operation": "individual_check_execution", "check_name": "cached_redis_check", "duration": 120.453, "error_type": "CancelledError", "correlation_id": "7ca5f456", "execution_id": "exec_1758044235_cdfd2aac", "critical": true, "timeout": 2.0}, "file": {"name": "logging_config.py", "path": "/home/toby/Projects/CleanBoard/backend/src/logging_config.py"}, "function": "__exit__", "level": {"icon": "❌", "name": "ERROR", "no": 40}, "line": 322, "message": "Failed individual_check_execution for cached_redis_check after 120.45ms: ", "module": "logging_config", "name": "logging_config", "process": {"id": 16891, "name": "MainProcess"}, "thread": {"id": 140530942503872, "name": "MainThread"}, "time": {"repr": "2025-09-16 11:37:15.878418-06:00", "timestamp": 1758044235.878418}}}
{"text": "2025-09-16 11:37:15.878 | ERROR    | logging_config:__exit__:322 - Failed individual_check_execution for slow_api_check after 122.05ms: \n", "record": {"elapsed": {"repr": "0:00:00.203040", "seconds": 0.20304}, "exception": null, "extra": {"service": "health-checker", "version": "0.0.1", "environment": "development", "component": "health_checker", "operation": "individual_check_execution", "check_name": "slow_api_check", "duration": 122.046, "error_type": "CancelledError", "correlation_id": "7ca5f456", "execution_id": "exec_1758044235_cdfd2aac", "critical": false, "timeout": 2.0}, "file": {"name": "logging_config.py", "path": "/home/toby/Projects/CleanBoard/backend/src/logging_config.py"}, "function": "__exit__", "level": {"icon": "❌", "name": "ERROR", "no": 40}, "line": 322, "message": "Failed individual_check_execution for slow_api_check after 122.05ms: ", "module": "logging_config", "name": "logging_config", "process": {"id": 16891, "name": "MainProcess"}, "thread": {"id": 140530942503872, "name": "MainThread"}, "time": {"repr": "2025-09-16 11:37:15.878841-06:00", "timestamp": 1758044235.878841}}}
{"text": "2025-09-16 11:37:15.879 | ERROR    | logging_config:__exit__:322 - Failed individual_check_execution for exception_check after 121.68ms: \n", "record": {"elapsed": {"repr": "0:00:00.203430", "seconds": 0.20343}, "exception": null, "extra": {"service": "health-checker", "version": "0.0.1", "environment": "development", "component": "health_checker", "operation": "individual_check_execution", "check_name": "exception_check", "duration": 121.681, "error_type": "CancelledError", "correlation_id": "7ca5f456", "execution_id": "exec_1758044235_cdfd2aac", "critical": true, "timeout": 2.0}, "file": {"name": "logging_config.py", "path": "/home/toby/Projects/CleanBoard/backend/src/logging_config.py"}, "function": "__exit__", "level": {"icon": "❌", "name": "ERROR", "no": 40}, "line": 322, "message": "Failed individual_check_execution for exception_check after 121.68ms: ", "module": "logging_config", "name": "logging_config", "process": {"id": 16891, "name": "MainProcess"}, "thread": {"id": 140530942503872, "name": "MainThread"}, "time": {"repr": "2025-09-16 11:37:15.879231-06:00", "timestamp": 1758044235.879231}}}
{"text": "2025-09-16 11:37:15.879 | ERROR    | logging_config:__exit__:322 - Failed individual_check_execution for cached_elasticsearch_check after 121.38ms: \n", "record": {"elapsed": {"repr": "0:00:00.203783", "seconds": 0.203783}, "exception": null, "extra": {"service": "health-checker", "version": "0.0.1", "environment": "development", "component": "health_checker", "operation": "individual_check_execution", "check_name": "cached_elasticsearch_check", "duration": 121.38300000000001, "error_type": "CancelledError", "correlation_id": "7ca5f456", "execution_id": "exec_1758044235_cdfd2aac", "critical": false, "timeout": 2.0}, "file": {"name": "logging_config.py", "path": "/home/toby/Projects/CleanBoard/backend/src/logging_config.py"}, "function": "__exit__", "level": {"icon": "❌", "name": "ERROR", "no": 40}, "line": 322, "message": "Failed individual_check_execution for cached_elasticsearch_check after 121.38ms: ", "module": "logging_config", "name": "logging_config", "process": {"id": 16891, "name": "MainProcess"}, "thread": {"id": 140530942503872, "name": "MainThread"}, "time": {"repr": "2025-09-16 11:37:15.879584-06:00", "timestamp": 1758044235.879584}}}
